{DataVersion:3953,size:[17,7,9],palette:["minecraft:water[level=0]","minecraft:mossy_stone_bricks","minecraft:oak_planks","minecraft:spruce_planks","minecraft:stone_bricks","minecraft:oak_fence","minecraft:spruce_fence","minecraft:lantern"],data:[{pos:[0,0,0],state:"minecraft:water[level=0]"},{pos:[1,0,0],state:"minecraft:water[level=0]"},{pos:[2,0,0],state:"minecraft:water[level=0]"},{pos:[3,0,0],state:"minecraft:water[level=0]"},{pos:[4,0,0],state:"minecraft:water[level=0]"},{pos:[5,0,0],state:"minecraft:water[level=0]"},{pos:[6,0,0],state:"minecraft:water[level=0]"},{pos:[7,0,0],state:"minecraft:water[level=0]"},{pos:[8,0,0],state:"minecraft:water[level=0]"},{pos:[9,0,0],state:"minecraft:water[level=0]"},{pos:[10,0,0],state:"minecraft:water[level=0]"},{pos:[11,0,0],state:"minecraft:water[level=0]"},{pos:[12,0,0],state:"minecraft:water[level=0]"},{pos:[13,0,0],state:"minecraft:water[level=0]"},{pos:[14,0,0],state:"minecraft:water[level=0]"},{pos:[15,0,0],state:"minecraft:water[level=0]"},{pos:[16,0,0],state:"minecraft:water[level=0]"},{pos:[0,0,1],state:"minecraft:water[level=0]"},{pos:[1,0,1],state:"minecraft:water[level=0]"},{pos:[2,0,1],state:"minecraft:water[level=0]"},{pos:[3,0,1],state:"minecraft:water[level=0]"},{pos:[4,0,1],state:"minecraft:water[level=0]"},{pos:[5,0,1],state:"minecraft:water[level=0]"},{pos:[6,0,1],state:"minecraft:water[level=0]"},{pos:[7,0,1],state:"minecraft:water[level=0]"},{pos:[8,0,1],state:"minecraft:water[level=0]"},{pos:[9,0,1],state:"minecraft:water[level=0]"},{pos:[10,0,1],state:"minecraft:water[level=0]"},{pos:[11,0,1],state:"minecraft:water[level=0]"},{pos:[12,0,1],state:"minecraft:water[level=0]"},{pos:[13,0,1],state:"minecraft:water[level=0]"},{pos:[14,0,1],state:"minecraft:water[level=0]"},{pos:[15,0,1],state:"minecraft:water[level=0]"},{pos:[16,0,1],state:"minecraft:water[level=0]"},{pos:[0,0,2],state:"minecraft:water[level=0]"},{pos:[1,0,2],state:"minecraft:water[level=0]"},{pos:[2,0,2],state:"minecraft:water[level=0]"},{pos:[3,0,2],state:"minecraft:water[level=0]"},{pos:[4,0,2],state:"minecraft:water[level=0]"},{pos:[5,0,2],state:"minecraft:water[level=0]"},{pos:[6,0,2],state:"minecraft:water[level=0]"},{pos:[7,0,2],state:"minecraft:water[level=0]"},{pos:[8,0,2],state:"minecraft:water[level=0]"},{pos:[9,0,2],state:"minecraft:water[level=0]"},{pos:[10,0,2],state:"minecraft:water[level=0]"},{pos:[11,0,2],state:"minecraft:water[level=0]"},{pos:[12,0,2],state:"minecraft:water[level=0]"},{pos:[13,0,2],state:"minecraft:water[level=0]"},{pos:[14,0,2],state:"minecraft:water[level=0]"},{pos:[15,0,2],state:"minecraft:water[level=0]"},{pos:[16,0,2],state:"minecraft:water[level=0]"},{pos:[0,0,3],state:"minecraft:water[level=0]"},{pos:[1,0,3],state:"minecraft:water[level=0]"},{pos:[2,0,3],state:"minecraft:mossy_stone_bricks"},{pos:[3,0,3],state:"minecraft:water[level=0]"},{pos:[4,0,3],state:"minecraft:water[level=0]"},{pos:[5,0,3],state:"minecraft:water[level=0]"},{pos:[6,0,3],state:"minecraft:water[level=0]"},{pos:[7,0,3],state:"minecraft:water[level=0]"},{pos:[8,0,3],state:"minecraft:mossy_stone_bricks"},{pos:[9,0,3],state:"minecraft:water[level=0]"},{pos:[10,0,3],state:"minecraft:water[level=0]"},{pos:[11,0,3],state:"minecraft:water[level=0]"},{pos:[12,0,3],state:"minecraft:water[level=0]"},{pos:[13,0,3],state:"minecraft:water[level=0]"},{pos:[14,0,3],state:"minecraft:mossy_stone_bricks"},{pos:[15,0,3],state:"minecraft:water[level=0]"},{pos:[16,0,3],state:"minecraft:water[level=0]"},{pos:[0,0,4],state:"minecraft:water[level=0]"},{pos:[1,0,4],state:"minecraft:water[level=0]"},{pos:[2,0,4],state:"minecraft:water[level=0]"},{pos:[3,0,4],state:"minecraft:water[level=0]"},{pos:[4,0,4],state:"minecraft:water[level=0]"},{pos:[5,0,4],state:"minecraft:water[level=0]"},{pos:[6,0,4],state:"minecraft:water[level=0]"},{pos:[7,0,4],state:"minecraft:water[level=0]"},{pos:[8,0,4],state:"minecraft:water[level=0]"},{pos:[9,0,4],state:"minecraft:water[level=0]"},{pos:[10,0,4],state:"minecraft:water[level=0]"},{pos:[11,0,4],state:"minecraft:water[level=0]"},{pos:[12,0,4],state:"minecraft:water[level=0]"},{pos:[13,0,4],state:"minecraft:water[level=0]"},{pos:[14,0,4],state:"minecraft:water[level=0]"},{pos:[15,0,4],state:"minecraft:water[level=0]"},{pos:[16,0,4],state:"minecraft:water[level=0]"},{pos:[0,0,5],state:"minecraft:water[level=0]"},{pos:[1,0,5],state:"minecraft:water[level=0]"},{pos:[2,0,5],state:"minecraft:mossy_stone_bricks"},{pos:[3,0,5],state:"minecraft:water[level=0]"},{pos:[4,0,5],state:"minecraft:water[level=0]"},{pos:[5,0,5],state:"minecraft:water[level=0]"},{pos:[6,0,5],state:"minecraft:water[level=0]"},{pos:[7,0,5],state:"minecraft:water[level=0]"},{pos:[8,0,5],state:"minecraft:mossy_stone_bricks"},{pos:[9,0,5],state:"minecraft:water[level=0]"},{pos:[10,0,5],state:"minecraft:water[level=0]"},{pos:[11,0,5],state:"minecraft:water[level=0]"},{pos:[12,0,5],state:"minecraft:water[level=0]"},{pos:[13,0,5],state:"minecraft:water[level=0]"},{pos:[14,0,5],state:"minecraft:mossy_stone_bricks"},{pos:[15,0,5],state:"minecraft:water[level=0]"},{pos:[16,0,5],state:"minecraft:water[level=0]"},{pos:[0,0,6],state:"minecraft:water[level=0]"},{pos:[1,0,6],state:"minecraft:water[level=0]"},{pos:[2,0,6],state:"minecraft:water[level=0]"},{pos:[3,0,6],state:"minecraft:water[level=0]"},{pos:[4,0,6],state:"minecraft:water[level=0]"},{pos:[5,0,6],state:"minecraft:water[level=0]"},{pos:[6,0,6],state:"minecraft:water[level=0]"},{pos:[7,0,6],state:"minecraft:water[level=0]"},{pos:[8,0,6],state:"minecraft:water[level=0]"},{pos:[9,0,6],state:"minecraft:water[level=0]"},{pos:[10,0,6],state:"minecraft:water[level=0]"},{pos:[11,0,6],state:"minecraft:water[level=0]"},{pos:[12,0,6],state:"minecraft:water[level=0]"},{pos:[13,0,6],state:"minecraft:water[level=0]"},{pos:[14,0,6],state:"minecraft:water[level=0]"},{pos:[15,0,6],state:"minecraft:water[level=0]"},{pos:[16,0,6],state:"minecraft:water[level=0]"},{pos:[0,0,7],state:"minecraft:water[level=0]"},{pos:[1,0,7],state:"minecraft:water[level=0]"},{pos:[2,0,7],state:"minecraft:water[level=0]"},{pos:[3,0,7],state:"minecraft:water[level=0]"},{pos:[4,0,7],state:"minecraft:water[level=0]"},{pos:[5,0,7],state:"minecraft:water[level=0]"},{pos:[6,0,7],state:"minecraft:water[level=0]"},{pos:[7,0,7],state:"minecraft:water[level=0]"},{pos:[8,0,7],state:"minecraft:water[level=0]"},{pos:[9,0,7],state:"minecraft:water[level=0]"},{pos:[10,0,7],state:"minecraft:water[level=0]"},{pos:[11,0,7],state:"minecraft:water[level=0]"},{pos:[12,0,7],state:"minecraft:water[level=0]"},{pos:[13,0,7],state:"minecraft:water[level=0]"},{pos:[14,0,7],state:"minecraft:water[level=0]"},{pos:[15,0,7],state:"minecraft:water[level=0]"},{pos:[16,0,7],state:"minecraft:water[level=0]"},{pos:[0,0,8],state:"minecraft:water[level=0]"},{pos:[1,0,8],state:"minecraft:water[level=0]"},{pos:[2,0,8],state:"minecraft:water[level=0]"},{pos:[3,0,8],state:"minecraft:water[level=0]"},{pos:[4,0,8],state:"minecraft:water[level=0]"},{pos:[5,0,8],state:"minecraft:water[level=0]"},{pos:[6,0,8],state:"minecraft:water[level=0]"},{pos:[7,0,8],state:"minecraft:water[level=0]"},{pos:[8,0,8],state:"minecraft:water[level=0]"},{pos:[9,0,8],state:"minecraft:water[level=0]"},{pos:[10,0,8],state:"minecraft:water[level=0]"},{pos:[11,0,8],state:"minecraft:water[level=0]"},{pos:[12,0,8],state:"minecraft:water[level=0]"},{pos:[13,0,8],state:"minecraft:water[level=0]"},{pos:[14,0,8],state:"minecraft:water[level=0]"},{pos:[15,0,8],state:"minecraft:water[level=0]"},{pos:[16,0,8],state:"minecraft:water[level=0]"},{pos:[2,1,3],state:"minecraft:stone_bricks"},{pos:[8,1,3],state:"minecraft:stone_bricks"},{pos:[14,1,3],state:"minecraft:stone_bricks"},{pos:[2,1,4],state:"minecraft:stone_bricks"},{pos:[8,1,4],state:"minecraft:stone_bricks"},{pos:[14,1,4],state:"minecraft:stone_bricks"},{pos:[2,1,5],state:"minecraft:stone_bricks"},{pos:[8,1,5],state:"minecraft:stone_bricks"},{pos:[14,1,5],state:"minecraft:stone_bricks"},{pos:[0,2,3],state:"minecraft:stone_bricks"},{pos:[1,2,3],state:"minecraft:stone_bricks"},{pos:[2,2,3],state:"minecraft:stone_bricks"},{pos:[8,2,3],state:"minecraft:stone_bricks"},{pos:[14,2,3],state:"minecraft:stone_bricks"},{pos:[15,2,3],state:"minecraft:stone_bricks"},{pos:[16,2,3],state:"minecraft:stone_bricks"},{pos:[0,2,4],state:"minecraft:stone_bricks"},{pos:[1,2,4],state:"minecraft:stone_bricks"},{pos:[2,2,4],state:"minecraft:stone_bricks"},{pos:[8,2,4],state:"minecraft:stone_bricks"},{pos:[14,2,4],state:"minecraft:stone_bricks"},{pos:[15,2,4],state:"minecraft:stone_bricks"},{pos:[16,2,4],state:"minecraft:stone_bricks"},{pos:[0,2,5],state:"minecraft:stone_bricks"},{pos:[1,2,5],state:"minecraft:stone_bricks"},{pos:[2,2,5],state:"minecraft:stone_bricks"},{pos:[8,2,5],state:"minecraft:stone_bricks"},{pos:[14,2,5],state:"minecraft:stone_bricks"},{pos:[15,2,5],state:"minecraft:stone_bricks"},{pos:[16,2,5],state:"minecraft:stone_bricks"},{pos:[0,3,2],state:"minecraft:spruce_planks"},{pos:[1,3,2],state:"minecraft:spruce_planks"},{pos:[2,3,2],state:"minecraft:spruce_planks"},{pos:[3,3,2],state:"minecraft:spruce_planks"},{pos:[4,3,2],state:"minecraft:spruce_planks"},{pos:[5,3,2],state:"minecraft:spruce_planks"},{pos:[6,3,2],state:"minecraft:spruce_planks"},{pos:[7,3,2],state:"minecraft:spruce_planks"},{pos:[8,3,2],state:"minecraft:spruce_planks"},{pos:[9,3,2],state:"minecraft:spruce_planks"},{pos:[10,3,2],state:"minecraft:spruce_planks"},{pos:[11,3,2],state:"minecraft:spruce_planks"},{pos:[12,3,2],state:"minecraft:spruce_planks"},{pos:[13,3,2],state:"minecraft:spruce_planks"},{pos:[14,3,2],state:"minecraft:spruce_planks"},{pos:[15,3,2],state:"minecraft:spruce_planks"},{pos:[16,3,2],state:"minecraft:spruce_planks"},{pos:[0,3,3],state:"minecraft:oak_planks"},{pos:[1,3,3],state:"minecraft:oak_planks"},{pos:[2,3,3],state:"minecraft:oak_planks"},{pos:[3,3,3],state:"minecraft:oak_planks"},{pos:[4,3,3],state:"minecraft:oak_planks"},{pos:[5,3,3],state:"minecraft:oak_planks"},{pos:[6,3,3],state:"minecraft:oak_planks"},{pos:[7,3,3],state:"minecraft:oak_planks"},{pos:[8,3,3],state:"minecraft:oak_planks"},{pos:[9,3,3],state:"minecraft:oak_planks"},{pos:[10,3,3],state:"minecraft:oak_planks"},{pos:[11,3,3],state:"minecraft:oak_planks"},{pos:[12,3,3],state:"minecraft:oak_planks"},{pos:[13,3,3],state:"minecraft:oak_planks"},{pos:[14,3,3],state:"minecraft:oak_planks"},{pos:[15,3,3],state:"minecraft:oak_planks"},{pos:[16,3,3],state:"minecraft:oak_planks"},{pos:[0,3,4],state:"minecraft:oak_planks"},{pos:[1,3,4],state:"minecraft:oak_planks"},{pos:[2,3,4],state:"minecraft:oak_planks"},{pos:[3,3,4],state:"minecraft:oak_planks"},{pos:[4,3,4],state:"minecraft:oak_planks"},{pos:[5,3,4],state:"minecraft:oak_planks"},{pos:[6,3,4],state:"minecraft:oak_planks"},{pos:[7,3,4],state:"minecraft:oak_planks"},{pos:[8,3,4],state:"minecraft:oak_planks"},{pos:[9,3,4],state:"minecraft:oak_planks"},{pos:[10,3,4],state:"minecraft:oak_planks"},{pos:[11,3,4],state:"minecraft:oak_planks"},{pos:[12,3,4],state:"minecraft:oak_planks"},{pos:[13,3,4],state:"minecraft:oak_planks"},{pos:[14,3,4],state:"minecraft:oak_planks"},{pos:[15,3,4],state:"minecraft:oak_planks"},{pos:[16,3,4],state:"minecraft:oak_planks"},{pos:[0,3,5],state:"minecraft:oak_planks"},{pos:[1,3,5],state:"minecraft:oak_planks"},{pos:[2,3,5],state:"minecraft:oak_planks"},{pos:[3,3,5],state:"minecraft:oak_planks"},{pos:[4,3,5],state:"minecraft:oak_planks"},{pos:[5,3,5],state:"minecraft:oak_planks"},{pos:[6,3,5],state:"minecraft:oak_planks"},{pos:[7,3,5],state:"minecraft:oak_planks"},{pos:[8,3,5],state:"minecraft:oak_planks"},{pos:[9,3,5],state:"minecraft:oak_planks"},{pos:[10,3,5],state:"minecraft:oak_planks"},{pos:[11,3,5],state:"minecraft:oak_planks"},{pos:[12,3,5],state:"minecraft:oak_planks"},{pos:[13,3,5],state:"minecraft:oak_planks"},{pos:[14,3,5],state:"minecraft:oak_planks"},{pos:[15,3,5],state:"minecraft:oak_planks"},{pos:[16,3,5],state:"minecraft:oak_planks"},{pos:[0,3,6],state:"minecraft:spruce_planks"},{pos:[1,3,6],state:"minecraft:spruce_planks"},{pos:[2,3,6],state:"minecraft:spruce_planks"},{pos:[3,3,6],state:"minecraft:spruce_planks"},{pos:[4,3,6],state:"minecraft:spruce_planks"},{pos:[5,3,6],state:"minecraft:spruce_planks"},{pos:[6,3,6],state:"minecraft:spruce_planks"},{pos:[7,3,6],state:"minecraft:spruce_planks"},{pos:[8,3,6],state:"minecraft:spruce_planks"},{pos:[9,3,6],state:"minecraft:spruce_planks"},{pos:[10,3,6],state:"minecraft:spruce_planks"},{pos:[11,3,6],state:"minecraft:spruce_planks"},{pos:[12,3,6],state:"minecraft:spruce_planks"},{pos:[13,3,6],state:"minecraft:spruce_planks"},{pos:[14,3,6],state:"minecraft:spruce_planks"},{pos:[15,3,6],state:"minecraft:spruce_planks"},{pos:[16,3,6],state:"minecraft:spruce_planks"},{pos:[0,4,2],state:"minecraft:spruce_fence"},{pos:[1,4,2],state:"minecraft:oak_fence"},{pos:[2,4,2],state:"minecraft:oak_fence"},{pos:[3,4,2],state:"minecraft:oak_fence"},{pos:[4,4,2],state:"minecraft:oak_fence"},{pos:[5,4,2],state:"minecraft:oak_fence"},{pos:[6,4,2],state:"minecraft:oak_fence"},{pos:[7,4,2],state:"minecraft:oak_fence"},{pos:[8,4,2],state:"minecraft:oak_fence"},{pos:[9,4,2],state:"minecraft:oak_fence"},{pos:[10,4,2],state:"minecraft:oak_fence"},{pos:[11,4,2],state:"minecraft:oak_fence"},{pos:[12,4,2],state:"minecraft:oak_fence"},{pos:[13,4,2],state:"minecraft:oak_fence"},{pos:[14,4,2],state:"minecraft:oak_fence"},{pos:[15,4,2],state:"minecraft:oak_fence"},{pos:[16,4,2],state:"minecraft:spruce_fence"},{pos:[0,4,6],state:"minecraft:spruce_fence"},{pos:[1,4,6],state:"minecraft:oak_fence"},{pos:[2,4,6],state:"minecraft:oak_fence"},{pos:[3,4,6],state:"minecraft:oak_fence"},{pos:[4,4,6],state:"minecraft:oak_fence"},{pos:[5,4,6],state:"minecraft:oak_fence"},{pos:[6,4,6],state:"minecraft:oak_fence"},{pos:[7,4,6],state:"minecraft:oak_fence"},{pos:[8,4,6],state:"minecraft:oak_fence"},{pos:[9,4,6],state:"minecraft:oak_fence"},{pos:[10,4,6],state:"minecraft:oak_fence"},{pos:[11,4,6],state:"minecraft:oak_fence"},{pos:[12,4,6],state:"minecraft:oak_fence"},{pos:[13,4,6],state:"minecraft:oak_fence"},{pos:[14,4,6],state:"minecraft:oak_fence"},{pos:[15,4,6],state:"minecraft:oak_fence"},{pos:[16,4,6],state:"minecraft:spruce_fence"},{pos:[0,5,2],state:"minecraft:spruce_fence"},{pos:[1,5,2],state:"minecraft:oak_fence"},{pos:[15,5,2],state:"minecraft:oak_fence"},{pos:[16,5,2],state:"minecraft:spruce_fence"},{pos:[0,5,6],state:"minecraft:spruce_fence"},{pos:[1,5,6],state:"minecraft:oak_fence"},{pos:[15,5,6],state:"minecraft:oak_fence"},{pos:[16,5,6],state:"minecraft:spruce_fence"},{pos:[1,6,2],state:"minecraft:lantern"},{pos:[15,6,2],state:"minecraft:lantern"},{pos:[1,6,6],state:"minecraft:lantern"},{pos:[15,6,6],state:"minecraft:lantern"}],entities:[]}